Workbook

Sheet Executive_Report
A1: UrbanCart Retail: Executive Report (SYNTHETIC DATA)
A2: All numbers are formulas linked to the analysis sheets. Change the year on KPI_Summary!F4 to refresh the year column.
A4: Total Revenue | C4: Total Profit | E4: Profit Margin | G4: Orders
A5: =KPI_Summary!B5 | C5: =KPI_Summary!B7 | E5: =KPI_Summary!B8 | G5: =KPI_Summary!B10
A7: Customers | C7: Avg Order Value | E7: Return Rate | G7: Repeat Customers
A8: =KPI_Summary!B11 | C8: =KPI_Summary!B12 | E8: =KPI_Summary!B15 | G8: =Customer_Analysis!S23
A11: Selected-year view
A12: Year | B12: =KPI_Summary!F4
A13: Revenue | B13: =KPI_Summary!C5
A14: YoY growth | B14: =KPI_Summary!C16
A15: Margin health | B15: =KPI_Summary!C17
A17: Top region | B17: =INDEX(Regional_Analysis!A5:A9,MATCH(MAX(Regional_Analysis!B5:B9),Regional_Analysis!B5:B9,0))
A18: Top category | B18: =INDEX(Pivot_Analysis!A5:A11,MATCH(MAX(Pivot_Analysis!E5:E11),Pivot_Analysis!E5:E11,0))
A19: Top return reason | B19: =INDEX(Returns_Analysis!K5:K12,MATCH(MAX(Returns_Analysis!L5:L12),Returns_Analysis!L5:L12,0))

Sheet Raw_Data
A1: Raw Data: products.csv as received (synthetic)
A2: Unmodified source rows. Note the inconsistent categories, '₹1,299.00' text prices, blanks and duplicates (highlighted).
A4: product_id | B4: product_name | C4: category | D4: sub_category | E4: brand | F4: unit_price | G4: unit_cost | H4: launch_date | K4: Check | L4: Count
A5: P0001 | B5: Kriti Team Sports 315 | C5: Sports | D5: Team Sports | E5: Kriti | F5: 4759.0 | G5: 2727.11 | H5: 2023-10-20 | K5: Blank unit_cost | L5: =COUNTBLANK(G5:G529)
A6: P0002 | B6: Veltrix Storage 168 | C6: Home & Kitchen | D6: Storage | E6: Veltrix | F6: 269.0 | G6: 186.62 | H6: 2024-12-26 | K6: Text prices (contain ₹) | L6: =COUNTIF(F5:F529,"₹*")
A7: P0003 | B7: Mitti Non-Fiction 229 | C7: Books | D7: Non-Fiction | E7: Mitti | F7: 359.0 | G7: 252.43 | H7: 2024-02-12 | K7: Distinct category spellings | L7: =SUMPRODUCT(1/COUNTIF(C5:C529,C5:C529))
A8: P0004 | B8: Haveli Cycling 706 | C8: Sports | D8: Cycling | E8: Haveli | F8: 1729.0 | G8: 953.73 | H8: 2022-08-17
A9: P0005 | B9: Aarav Wearables 475 | C9: Electronics | D9: Wearables | E9: Aarav | F9: 16419.0 | G9: 13079.22 | H9: 2024-07-04
A10: P0006 | B10: Ember Personal Care 820 | C10: Groceries | D10: Personal Care | E10: Ember | F10: 219.0 | G10: 181.57 | H10: 2024-12-20
A11: P0007 | B11: Kavya Team Sports 395 | C11: Sports | D11: Team Sports | E11: Kavya | F11: 4919.0 | G11: 2995.11 | H11: 2022-03-29
A12: P0008 | B12: Mitti Children 926 | C12: Books | D12: Children | E12: Mitti | F12: 499.0 | G12: 334.53 | H12: 2022-06-14
A13: P0009 | B13: Kavya Laptops 668 | C13: Electronics | D13: Laptops | E13: Kavya | F13: 6009.0 | G13: 4713.85 | H13: 2022-09-12
A14: P0010 | B14: Solace Cookware 750 | C14: Home & Kitchen | D14: Cookware | E14: Solace | F14: 1169.0 | G14: 745.78 | H14: 2023-06-25
A15: P0011 | B15: Veltrix Men Apparel 867 | C15: Fashion | D15: Men Apparel | E15: Veltrix | F15: 469.0 | G15: 260.28 | H15: 2023-11-30
A16: P0012 | B16: Pragati Beverages 651 | C16: grocery | D16: Beverages | E16: Pragati | F16: 309.0 | G16: 253.13 | H16: 2022-03-05
A17: P0013 | B17: Trendo Makeup 937 | C17: Beauty | D17: Makeup | E17: Trendo | F17: 919.0 | H17: 2024-07-13
A18: P0014 | B18: Zephyr Non-Fiction 432 | C18: books | D18: Non-Fiction | E18: Zephyr | F18: 509.0 | G18: 370.45 | H18: 2023-07-07
A19: P0015 | B19: Vayu Furnishing 445 | C19: Home & Kitchen | D19: Furnishing | E19: Vayu | F19: 989.0 | G19: 670.09 | H19: 2023-01-08
A20: P0016 | B20: Zephyr Footwear 119 | C20: Fashion | D20: Footwear | E20: Zephyr | F20: ₹959.00 | G20: 418.89 | H20: 2023-03-13
A21: P0017 | B21: Vayu Decor 107 | C21: Home & Kitchen | D21: Decor | E21: Vayu | F21: 1879.0 | G21: 1083.48 | H21: 2023-01-07
A22: P0018 | B22: UrbanLeaf Laptops 721 | C22: Electronics | D22: Laptops | E22: UrbanLeaf | F22: 7799.0 | G22: 6806.55 | H22: 2023-05-06
A23: P0019 | B23: Solace Non-Fiction 473 | C23: Books | D23: Non-Fiction | E23: Solace | F23: 249.0 | G23: 149.67 | H23: 2022-11-01
A24: P0020 | B24: Orbit Skincare 821 | C24: Beauty | D24: Skincare | E24: Orbit | F24: 669.0 | G24: 399.57 | H24: 2023-11-11
A25: P0021 | B25: Zephyr Cycling 563 | C25: Sports | D25: Cycling | E25: Zephyr | F25: 1309.0 | G25: 897.32 | H25: 2024-02-29
A26: P0022 | B26: Ember Women Apparel 166 | C26: Fashion | D26: Women Apparel | E26: Ember | F26: 1089.0 | G26: 608.41 | H26: 2022-05-05
A27: P0023 | B27: Orbit Beverages 964 | C27: Grocery | D27: Beverages | E27: Orbit | F27: 189.0 | G27: 149.67 | H27: 2023-12-18
A28: P0024 | B28: Ember Snacks 838 | C28: Grocery | D28: Snacks | E28: Ember | F28: 189.0 | G28: 143.16 | H28: 2024-03-14
A29: P0025 | B29: Orbit Cycling 367 | C29: Sports | D29: Cycling | E29: Orbit | F29: 1139.0 | G29: 647.61 | H29: 2022-02-14
... A73: P0069 | B73: Trendo Wearables 761 | C73: electronics | D73: Wearables | E73: Trendo | F73: ₹15,969.00 | G73: 12503.46 | H73: 2023-01-15
A74: P0070 | B74: Nexora Appliances 859 | C74: Home & Kitchen | D74: Appliances | E74: Nexora | F74: 1149.0 | H74: 2024-02-15
A75: P0071 | B75: Orbit Women Apparel 232 | C75: Fashion | D75: Women Apparel | E75: Orbit | F75: 2939.0 | G75: 1652.9 | H75: 2023-10-13
A76: P0072 | B76: Kavya Appliances 154 | C76: Home & Kitchen | D76: Appliances | E76: Kavya | F76: 2119.0 | G76: 1385.75 | H76: 2022-07-09
A77: P0073 | B77: Aarav Children 930 | C77: Books | D77: Children | E77: Aarav | F77: 269.0 | G77: 161.56 | H77: 2022-01-19
A78: P0074 | B78: Ember Footwear 614 | C78: Fashion | D78: Footwear | E78: Ember | F78: 2219.0 | G78: 977.04 | H78: 2024-09-09
A79: P0075 | B79: Vayu Smartphones 263 | C79: Electronics | D79: Smartphones | E79: Vayu | F79: 7499.0 | G79: 6315.5 | H79: 2022-10-27
A80: P0076 | B80: Nexora Ethnic Wear 408 | C80: Fashion | D80: Ethnic Wear | E80: Nexora | F80: 609.0 | G80: 284.5 | H80: 2023-12-28
A81: P0077 | B81: Kriti Accessories 240 | C81: Fashion | D81: Accessories | E81: Kriti | F81: 1209.0 | G81: 623.01 | H81: 2022-09-11
A82: P0078 | B82: Kriti Fragrance 266 | C82: beauty | D82: Fragrance | E82: Kriti | F82: 609.0 | G82: 329.84 | H82: 2023-08-30
A83: P0079 | B83: Haveli Furnishing 786 | C83: Home & Kitchen | D83: Furnishing | E83: Haveli | F83: 2439.0 | G83: 1606.97 | H83: 2023-09-13
A84: P0080 | B84: Mitti Non-Fiction 930 | C84: Books | D84: Non-Fiction | E84: Mitti | F84: 269.0 | G84: 178.32 | H84: 2023-07-18
...

Sheet Cleaned_Data
A1: Cleaned Data: monthly sales cube from the star schema
A2: Grain: month x region x channel x category. Columns K-O are Excel formulas (profit, margin, year, quarter, month).
A4: month_start | B4: region_name | C4: channel_name | D4: category | E4: revenue | F4: cost | G4: gross | H4: units | I4: lines | J4: returned_lines | K4: profit | L4: margin | M4: year | N4: quarter | O4: month_name
A5: 44927 | B5: Central | C5: Marketplace | D5: Beauty | E5: 3238.6 | F5: 1873.24 | G5: 3614 | H5: 6 | I5: 4 | J5: 1 | K5: =E5-F5 | L5: =IFERROR(K5/E5,0) | M5: =YEAR(A5) | N5: ="Q"&ROUNDUP(MONTH(A5)/3,0) | O5: =TEXT(A5,"mmm")
A6: 44927 | B6: Central | C6: Marketplace | D6: Books | E6: 4246.35 | F6: 3121.34 | G6: 4579 | H6: 11 | I6: 8 | J6: 0 | K6: =E6-F6 | L6: =IFERROR(K6/E6,0) | M6: =YEAR(A6) | N6: ="Q"&ROUNDUP(MONTH(A6)/3,0) | O6: =TEXT(A6,"mmm")
A7: 44927 | B7: Central | C7: Marketplace | D7: Electronics | E7: 70742.05 | F7: 63034.45 | G7: 76873 | H7: 7 | I7: 7 | J7: 0 | K7: =E7-F7 | L7: =IFERROR(K7/E7,0) | M7: =YEAR(A7) | N7: ="Q"&ROUNDUP(MONTH(A7)/3,0) | O7: =TEXT(A7,"mmm")
A8: 44927 | B8: Central | C8: Marketplace | D8: Fashion | E8: 12008.9 | F8: 6734.04 | G8: 13200 | H8: 10 | I8: 8 | J8: 3 | K8: =E8-F8 | L8: =IFERROR(K8/E8,0) | M8: =YEAR(A8) | N8: ="Q"&ROUNDUP(MONTH(A8)/3,0) | O8: =TEXT(A8,"mmm")
A9: 44927 | B9: Central | C9: Marketplace | D9: Grocery | E9: 5877.45 | F9: 4903.55 | G9: 6373 | H9: 17 | I9: 7 | J9: 0 | K9: =E9-F9 | L9: =IFERROR(K9/E9,0) | M9: =YEAR(A9) | N9: ="Q"&ROUNDUP(MONTH(A9)/3,0) | O9: =TEXT(A9,"mmm")
A10: 44927 | B10: Central | C10: Marketplace | D10: Home & Kitchen | E10: 20179.05 | F10: 13806.28 | G10: 21212 | H10: 8 | I10: 7 | J10: 1 | K10: =E10-F10 | L10: =IFERROR(K10/E10,0) | M10: =YEAR(A10) | N10: ="Q"&ROUNDUP(MONTH(A10)/3,0) | O10: =TEXT(A10,"mmm")
A11: 44927 | B11: Central | C11: Marketplace | D11: Sports | E11: 7215.75 | F11: 4819.74 | G11: 8172 | H11: 8 | I11: 7 | J11: 0 | K11: =E11-F11 | L11: =IFERROR(K11/E11,0) | M11: =YEAR(A11) | N11: ="Q"&ROUNDUP(MONTH(A11)/3,0) | O11: =TEXT(A11,"mmm")
A12: 44927 | B12: Central | C12: Mobile App | D12: Beauty | E12: 2699.05 | F12: 1462.44 | G12: 3004 | H12: 6 | I12: 6 | J12: 0 | K12: =E12-F12 | L12: =IFERROR(K12/E12,0) | M12: =YEAR(A12) | N12: ="Q"&ROUNDUP(MONTH(A12)/3,0) | O12: =TEXT(A12,"mmm")
A13: 44927 | B13: Central | C13: Mobile App | D13: Books | E13: 1758.6 | F13: 1272.01 | G13: 1954 | H13: 6 | I13: 4 | J13: 0 | K13: =E13-F13 | L13: =IFERROR(K13/E13,0) | M13: =YEAR(A13) | N13: ="Q"&ROUNDUP(MONTH(A13)/3,0) | O13: =TEXT(A13,"mmm")
A14: 44927 | B14: Central | C14: Mobile App | D14: Electronics | E14: 95109.95 | F14: 83280.4 | G14: 101343 | H14: 7 | I14: 5 | J14: 0 | K14: =E14-F14 | L14: =IFERROR(K14/E14,0) | M14: =YEAR(A14) | N14: ="Q"&ROUNDUP(MONTH(A14)/3,0) | O14: =TEXT(A14,"mmm")
A15: 44927 | B15: Central | C15: Mobile App | D15: Fashion | E15: 20874.45 | F15: 10558.77 | G15: 22347 | H15: 13 | I15: 11 | J15: 3 | K15: =E15-F15 | L15: =IFERROR(K15/E15,0) | M15: =YEAR(A15) | N15: ="Q"&ROUNDUP(MONTH(A15)/3,0) | O15: =TEXT(A15,"mmm")
A16: 44927 | B16: Central | C16: Mobile App | D16: Grocery | E16: 8993.15 | F16: 7515.9 | G16: 9773 | H16: 27 | I16: 11 | J16: 0 | K16: =E16-F16 | L16: =IFERROR(K16/E16,0) | M16: =YEAR(A16) | N16: ="Q"&ROUNDUP(MONTH(A16)/3,0) | O16: =TEXT(A16,"mmm")
... A5560: 45992 | B5560: West | C5560: Website | D5560: Sports | E5560: 29608.99 | F5560: 18870.74 | G5560: 31980.91 | H5560: 19 | I5560: 16 | J5560: 3 | K5560: =E5560-F5560 | L5560: =IFERROR(K5560/E5560,0) | M5560: =YEAR(A5560) | N5560: ="Q"&ROUNDUP(MONTH(A5560)/3,0) | O5560: =TEXT(A5560,"mmm")

Sheet Data_Quality
A1: Data Quality: scores, checks and cleaning log
A2: Status uses IFS; colours via conditional formatting.
A4: table | B4: raw | C4: clean | D4: improvement | E4: status
A5: customers | B5: 98.7 | C5: 99.8 | D5: =C5-B5 | E5: =_xlfn.IFS(C5>=99.5,"Good",C5>=98,"Watch",TRUE,"Poor")
A6: order_items | B6: 99.82 | C6: 100 | D6: =C6-B6 | E6: =_xlfn.IFS(C6>=99.5,"Good",C6>=98,"Watch",TRUE,"Poor")
A7: orders | B7: 95.26 | C7: 99.95 | D7: =C7-B7 | E7: =_xlfn.IFS(C7>=99.5,"Good",C7>=98,"Watch",TRUE,"Poor")
A8: payments | B8: 98.81 | C8: 99.88 | D8: =C8-B8 | E8: =_xlfn.IFS(C8>=99.5,"Good",C8>=98,"Watch",TRUE,"Poor")
A9: products | B9: 97.8 | C9: 99.97 | D9: =C9-B9 | E9: =_xlfn.IFS(C9>=99.5,"Good",C9>=98,"Watch",TRUE,"Poor")
A10: regions | B10: 94.44 | C10: 100 | D10: =C10-B10 | E10: =_xlfn.IFS(C10>=99.5,"Good",C10>=98,"Watch",TRUE,"Poor")
A11: returns | B11: 99.34 | C11: 99.75 | D11: =C11-B11 | E11: =_xlfn.IFS(C11>=99.5,"Good",C11>=98,"Watch",TRUE,"Poor")
A12: support_tickets | B12: 99.36 | C12: 99.8 | D12: =C12-B12 | E12: =_xlfn.IFS(C12>=99.5,"Good",C12>=98,"Watch",TRUE,"Poor")
A13: Overall | B13: =AVERAGE(B5:B12) | C13: =AVERAGE(C5:C12)
A15: Cleaning issue log
A16: table | B16: issue | C16: how_detected | D16: how_fixed | E16: rows_affected
A17: regions | B17: Extra whitespace in city | C17: value != TRIM(value) | D17: TRIM + collapse inner spaces | E17: 4
A18: regions | B18: Inconsistent region (zone) labels | C18: Distinct values outside the 5 allowed zones | D18: Lower/trim then map to canonical zone | E18: 8
A19: products | B19: Exact duplicate rows | C19: DataFrame.duplicated() | D19: Dropped duplicates | E19: 5
A20: products | B20: Inconsistent category names | C20: Values outside 7 canonical categories | D20: Case/space-insensitive mapping table | E20: 78
A21: products | B21: Price stored as text ('₹1,299.00') | C21: pd.to_numeric fails on raw value | D21: Removed currency symbol & separators, cast to float | E21: 26
A22: products | B22: Missing unit_cost | C22: IS NULL check | D22: Imputed = price x median cost ratio of same sub-category; flagged cost_imputed=True | E22: 15
A23: products | B23: Missing brand | C23: IS NULL check | D23: Set to 'Unbranded' | E23: 10
A24: customers | B24: Exact duplicate rows | C24: DataFrame.duplicated() | D24: Dropped | E24: 120
A25: customers | B25: Whitespace / inconsistent case in names & email | C25: value != TRIM(value), mixed case | D25: TRIM, Title-case names, lower-case email | E25: 1153
A26: customers | B26: Inconsistent gender codes (M/F/male) | C26: Values outside {Male, Female} | D26: Mapped to Male/Female; missing -> 'Not Specified' | E26: 611
A27: customers | B27: Invalid age (text 'unknown', negative, 150, 999) | C27: Non-numeric or outside 18-100 | D27: Set to NULL (not guessed) | E27: 175
A28: customers | B28: Invalid signup_date (2023-02-30, 'not available', future 2031) | C28: Fails ISO/dd-mm-yyyy parse or > snapshot date | D28: Set NULL, later imputed with customer's first order date (flag signup_date_imputed) | E28: 60
... A58: support_tickets | B58: CSAT outside 1-5 scale (0, 7, 10) | C58: Range check | D58: Set NULL | E58: 26
D59: Total rows fixed | E59: =SUM(E17:E58)
D60: Issues affecting >500 rows | E60: =COUNTIFS(E17:E58,">500")

Sheet KPI_Summary
A1: KPI Summary: all values are live formulas over Cleaned_Data and Customer_Analysis
A4: KPI | B4: All years | C4: Selected year | E4: Select year | F4: 2025
A5: Total Revenue | B5: =SUM(Cleaned_Data!$E$5:$E$5560) | C5: =SUMIFS(Cleaned_Data!$E$5:$E$5560,Cleaned_Data!$M$5:$M$5560,$F$4)
A6: Total Cost | B6: =SUM(Cleaned_Data!$F$5:$F$5560) | C6: =SUMIFS(Cleaned_Data!$F$5:$F$5560,Cleaned_Data!$M$5:$M$5560,$F$4)
A7: Total Profit | B7: =B5-B6 | C7: =C5-C6
A8: Profit Margin | B8: =IFERROR(B7/B5,0) | C8: =IFERROR(C7/C5,0)
A9: Units Sold | B9: =SUM(Cleaned_Data!$H$5:$H$5560) | C9: =SUMIFS(Cleaned_Data!$H$5:$H$5560,Cleaned_Data!$M$5:$M$5560,$F$4)
A10: Orders (identified customers) | B10: =SUM(Customer_Analysis!$G$5:$G$8806) | C10: -
A11: Customers (purchasing) | B11: =COUNTA(Customer_Analysis!$A$5:$A$8806) | C11: -
A12: Average Order Value (identified) | B12: =IFERROR(SUM(Customer_Analysis!$H$5:$H$8806)/B10,0) | C12: -
A13: Orders per Customer | B13: =IFERROR(B10/B11,0) | C13: -
A14: Average Discount % | B14: =IFERROR(1-SUM(Cleaned_Data!$E$5:$E$5560)/SUM(Cleaned_Data!$G$5:$G$5560),0) | C14: =IFERROR(1-C5/SUMIFS(Cleaned_Data!$G$5:$G$5560,Cleaned_Data!$M$5:$M$5560,$F$4),0)
A15: Return Rate (lines) | B15: =IFERROR(SUM(Cleaned_Data!$J$5:$J$5560)/SUM(Cleaned_Data!$I$5:$I$5560),0) | C15: =IFERROR(SUMIFS(Cleaned_Data!$J$5:$J$5560,Cleaned_Data!$M$5:$M$5560,$F$4)/SUMIFS(Cleaned_Data!$I$5:$I$5560,Cleaned_Data!$M$5:$M$5560,$F$4),0)
A16: Revenue YoY growth | B16: - | C16: =IFERROR(C5/SUMIFS(Cleaned_Data!$E$5:$E$5560,Cleaned_Data!$M$5:$M$5560,$F$4-1)-1,"n/a")
A17: Margin health | B17: =_xlfn.IFS(B8>=0.2,"Strong",B8>=0.15,"Healthy",B8>=0.1,"Watch",TRUE,"Weak") | C17: =_xlfn.IFS(C8>=0.2,"Strong",C8>=0.15,"Healthy",C8>=0.1,"Watch",TRUE,"Weak")
A20: Python cross-check (from pipeline headline_kpis.csv)
A21: KPI | B21: Python value | C21: Excel value | D21: Match?
A22: Total Revenue | B22: 3.8625952e+08 | C22: =B5 | D22: =IF(ABS(B22-C22)<1,"✔ Match","✖ Check")
A23: Orders (identified customers) | B23: 54529 | C23: =B10 | D23: =IF(ABS(B23-C23)<1,"✔ Match","✖ Check")
A24: Customers | B24: 8802 | C24: =B11 | D24: =IF(ABS(B24-C24)<1,"✔ Match","✖ Check")

Sheet Sales_Analysis
A1: Sales Analysis: monthly trend (SUMIFS), MoM, YoY, running and rolling totals
A4: Month | B4: Revenue | C4: Profit | D4: Margin | E4: MoM % | F4: YoY % | G4: Running revenue | H4: Rolling 3M | I4: Rolling 12M | J4: Month name | K4: Quarter
A5: =DATE(2023,1,1) | B5: =SUMIFS(Cleaned_Data!$E$5:$E$5560,Cleaned_Data!$A$5:$A$5560,A5) | C5: =SUMIFS(Cleaned_Data!$K$5:$K$5560,Cleaned_Data!$A$5:$A$5560,A5) | D5: =IFERROR(C5/B5,0) | G5: =SUM($B$5:B5) | J5: =TEXT(A5,"mmmm") | K5: ="Q"&ROUNDUP(MONTH(A5)/3,0)&"-"&YEAR(A5)
A6: =DATE(2023,2,1) | B6: =SUMIFS(Cleaned_Data!$E$5:$E$5560,Cleaned_Data!$A$5:$A$5560,A6) | C6: =SUMIFS(Cleaned_Data!$K$5:$K$5560,Cleaned_Data!$A$5:$A$5560,A6) | D6: =IFERROR(C6/B6,0) | E6: =IFERROR(B6/B5-1,"") | G6: =SUM($B$5:B6) | J6: =TEXT(A6,"mmmm") | K6: ="Q"&ROUNDUP(MONTH(A6)/3,0)&"-"&YEAR(A6)
A7: =DATE(2023,3,1) | B7: =SUMIFS(Cleaned_Data!$E$5:$E$5560,Cleaned_Data!$A$5:$A$5560,A7) | C7: =SUMIFS(Cleaned_Data!$K$5:$K$5560,Cleaned_Data!$A$5:$A$5560,A7) | D7: =IFERROR(C7/B7,0) | E7: =IFERROR(B7/B6-1,"") | G7: =SUM($B$5:B7) | H7: =SUM(B5:B7) | J7: =TEXT(A7,"mmmm") | K7: ="Q"&ROUNDUP(MONTH(A7)/3,0)&"-"&YEAR(A7)
A8: =DATE(2023,4,1) | B8: =SUMIFS(Cleaned_Data!$E$5:$E$5560,Cleaned_Data!$A$5:$A$5560,A8) | C8: =SUMIFS(Cleaned_Data!$K$5:$K$5560,Cleaned_Data!$A$5:$A$5560,A8) | D8: =IFERROR(C8/B8,0) | E8: =IFERROR(B8/B7-1,"") | G8: =SUM($B$5:B8) | H8: =SUM(B6:B8) | J8: =TEXT(A8,"mmmm") | K8: ="Q"&ROUNDUP(MONTH(A8)/3,0)&"-"&YEAR(A8)
A9: =DATE(2023,5,1) | B9: =SUMIFS(Cleaned_Data!$E$5:$E$5560,Cleaned_Data!$A$5:$A$5560,A9) | C9: =SUMIFS(Cleaned_Data!$K$5:$K$5560,Cleaned_Data!$A$5:$A$5560,A9) | D9: =IFERROR(C9/B9,0) | E9: =IFERROR(B9/B8-1,"") | G9: =SUM($B$5:B9) | H9: =SUM(B7:B9) | J9: =TEXT(A9,"mmmm") | K9: ="Q"&ROUNDUP(MONTH(A9)/3,0)&"-"&YEAR(A9)
A10: =DATE(2023,6,1) | B10: =SUMIFS(Cleaned_Data!$E$5:$E$5560,Cleaned_Data!$A$5:$A$5560,A10) | C10: =SUMIFS(Cleaned_Data!$K$5:$K$5560,Cleaned_Data!$A$5:$A$5560,A10) | D10: =IFERROR(C10/B10,0) | E10: =IFERROR(B10/B9-1,"") | G10: =SUM($B$5:B10) | H10: =SUM(B8:B10) | J10: =TEXT(A10,"mmmm") | K10: ="Q"&ROUNDUP(MONTH(A10)/3,0)&"-"&YEAR(A10)
A11: =DATE(2023,7,1) | B11: =SUMIFS(Cleaned_Data!$E$5:$E$5560,Cleaned_Data!$A$5:$A$5560,A11) | C11: =SUMIFS(Cleaned_Data!$K$5:$K$5560,Cleaned_Data!$A$5:$A$5560,A11) | D11: =IFERROR(C11/B11,0) | E11: =IFERROR(B11/B10-1,"") | G11: =SUM($B$5:B11) | H11: =SUM(B9:B11) | J11: =TEXT(A11,"mmmm") | K11: ="Q"&ROUNDUP(MONTH(A11)/3,0)&"-"&YEAR(A11)
A12: =DATE(2023,8,1) | B12: =SUMIFS(Cleaned_Data!$E$5:$E$5560,Cleaned_Data!$A$5:$A$5560,A12) | C12: =SUMIFS(Cleaned_Data!$K$5:$K$5560,Cleaned_Data!$A$5:$A$5560,A12) | D12: =IFERROR(C12/B12,0) | E12: =IFERROR(B12/B11-1,"") | G12: =SUM($B$5:B12) | H12: =SUM(B10:B12) | J12: =TEXT(A12,"mmmm") | K12: ="Q"&ROUNDUP(MONTH(A12)/3,0)&"-"&YEAR(A12)
A13: =DATE(2023,9,1) | B13: =SUMIFS(Cleaned_Data!$E$5:$E$5560,Cleaned_Data!$A$5:$A$5560,A13) | C13: =SUMIFS(Cleaned_Data!$K$5:$K$5560,Cleaned_Data!$A$5:$A$5560,A13) | D13: =IFERROR(C13/B13,0) | E13: =IFERROR(B13/B12-1,"") | G13: =SUM($B$5:B13) | H13: =SUM(B11:B13) | J13: =TEXT(A13,"mmmm") | K13: ="Q"&ROUNDUP(MONTH(A13)/3,0)&"-"&YEAR(A13)
A14: =DATE(2023,10,1) | B14: =SUMIFS(Cleaned_Data!$E$5:$E$5560,Cleaned_Data!$A$5:$A$5560,A14) | C14: =SUMIFS(Cleaned_Data!$K$5:$K$5560,Cleaned_Data!$A$5:$A$5560,A14) | D14: =IFERROR(C14/B14,0) | E14: =IFERROR(B14/B13-1,"") | G14: =SUM($B$5:B14) | H14: =SUM(B12:B14) | J14: =TEXT(A14,"mmmm") | K14: ="Q"&ROUNDUP(MONTH(A14)/3,0)&"-"&YEAR(A14)
A15: =DATE(2023,11,1) | B15: =SUMIFS(Cleaned_Data!$E$5:$E$5560,Cleaned_Data!$A$5:$A$5560,A15) | C15: =SUMIFS(Cleaned_Data!$K$5:$K$5560,Cleaned_Data!$A$5:$A$5560,A15) | D15: =IFERROR(C15/B15,0) | E15: =IFERROR(B15/B14-1,"") | G15: =SUM($B$5:B15) | H15: =SUM(B13:B15) | J15: =TEXT(A15,"mmmm") | K15: ="Q"&ROUNDUP(MONTH(A15)/3,0)&"-"&YEAR(A15)
A16: =DATE(2023,12,1) | B16: =SUMIFS(Cleaned_Data!$E$5:$E$5560,Cleaned_Data!$A$5:$A$5560,A16) | C16: =SUMIFS(Cleaned_Data!$K$5:$K$5560,Cleaned_Data!$A$5:$A$5560,A16) | D16: =IFERROR(C16/B16,0) | E16: =IFERROR(B16/B15-1,"") | G16: =SUM($B$5:B16) | H16: =SUM(B14:B16) | I16: =SUM(B5:B16) | J16: =TEXT(A16,"mmmm") | K16: ="Q"&ROUNDUP(MONTH(A16)/3,0)&"-"&YEAR(A16)
A17: =DATE(2024,1,1) | B17: =SUMIFS(Cleaned_Data!$E$5:$E$5560,Cleaned_Data!$A$5:$A$5560,A17) | C17: =SUMIFS(Cleaned_Data!$K$5:$K$5560,Cleaned_Data!$A$5:$A$5560,A17) | D17: =IFERROR(C17/B17,0) | E17: =IFERROR(B17/B16-1,"") | F17: =IFERROR(B17/B5-1,"") | G17: =SUM($B$5:B17) | H17: =SUM(B15:B17) | I17: =SUM(B6:B17) | J17: =TEXT(A17,"mmmm") | K17: ="Q"&ROUNDUP(MONTH(A17)/3,0)&"-"&YEAR(A17)
A18: =DATE(2024,2,1) | B18: =SUMIFS(Cleaned_Data!$E$5:$E$5560,Cleaned_Data!$A$5:$A$5560,A18) | C18: =SUMIFS(Cleaned_Data!$K$5:$K$5560,Cleaned_Data!$A$5:$A$5560,A18) | D18: =IFERROR(C18/B18,0) | E18: =IFERROR(B18/B17-1,"") | F18: =IFERROR(B18/B6-1,"") | G18: =SUM($B$5:B18) | H18: =SUM(B16:B18) | I18: =SUM(B7:B18) | J18: =TEXT(A18,"mmmm") | K18: ="Q"&ROUNDUP(MONTH(A18)/3,0)&"-"&YEAR(A18)
A19: =DATE(2024,3,1) | B19: =SUMIFS(Cleaned_Data!$E$5:$E$5560,Cleaned_Data!$A$5:$A$5560,A19) | C19: =SUMIFS(Cleaned_Data!$K$5:$K$5560,Cleaned_Data!$A$5:$A$5560,A19) | D19: =IFERROR(C19/B19,0) | E19: =IFERROR(B19/B18-1,"") | F19: =IFERROR(B19/B7-1,"") | G19: =SUM($B$5:B19) | H19: =SUM(B17:B19) | I19: =SUM(B8:B19) | J19: =TEXT(A19,"mmmm") | K19: ="Q"&ROUNDUP(MONTH(A19)/3,0)&"-"&YEAR(A19)
A20: =DATE(2024,4,1) | B20: =SUMIFS(Cleaned_Data!$E$5:$E$5560,Cleaned_Data!$A$5:$A$5560,A20) | C20: =SUMIFS(Cleaned_Data!$K$5:$K$5560,Cleaned_Data!$A$5:$A$5560,A20) | D20: =IFERROR(C20/B20,0) | E20: =IFERROR(B20/B19-1,"") | F20: =IFERROR(B20/B8-1,"") | G20: =SUM($B$5:B20) | H20: =SUM(B18:B20) | I20: =SUM(B9:B20) | J20: =TEXT(A20,"mmmm") | K20: ="Q"&ROUNDUP(MONTH(A20)/3,0)&"-"&YEAR(A20)
A21: =DATE(2024,5,1) | B21: =SUMIFS(Cleaned_Data!$E$5:$E$5560,Cleaned_Data!$A$5:$A$5560,A21) | C21: =SUMIFS(Cleaned_Data!$K$5:$K$5560,Cleaned_Data!$A$5:$A$5560,A21) | D21: =IFERROR(C21/B21,0) | E21: =IFERROR(B21/B20-1,"") | F21: =IFERROR(B21/B9-1,"") | G21: =SUM($B$5:B21) | H21: =SUM(B19:B21) | I21: =SUM(B10:B21) | J21: =TEXT(A21,"mmmm") | K21: ="Q"&ROUNDUP(MONTH(A21)/3,0)&"-"&YEAR(A21)
A22: =DATE(2024,6,1) | B22: =SUMIFS(Cleaned_Data!$E$5:$E$5560,Cleaned_Data!$A$5:$A$5560,A22) | C22: =SUMIFS(Cleaned_Data!$K$5:$K$5560,Cleaned_Data!$A$5:$A$5560,A22) | D22: =IFERROR(C22/B22,0) | E22: =IFERROR(B22/B21-1,"") | F22: =IFERROR(B22/B10-1,"") | G22: =SUM($B$5:B22) | H22: =SUM(B20:B22) | I22: =SUM(B11:B22) | J22: =TEXT(A22,"mmmm") | K22: ="Q"&ROUNDUP(MONTH(A22)/3,0)&"-"&YEAR(A22)
A23: =DATE(2024,7,1) | B23: =SUMIFS(Cleaned_Data!$E$5:$E$5560,Cleaned_Data!$A$5:$A$5560,A23) | C23: =SUMIFS(Cleaned_Data!$K$5:$K$5560,Cleaned_Data!$A$5:$A$5560,A23) | D23: =IFERROR(C23/B23,0) | E23: =IFERROR(B23/B22-1,"") | F23: =IFERROR(B23/B11-1,"") | G23: =SUM($B$5:B23) | H23: =SUM(B21:B23) | I23: =SUM(B12:B23) | J23: =TEXT(A23,"mmmm") | K23: ="Q"&ROUNDUP(MONTH(A23)/3,0)&"-"&YEAR(A23)
A24: =DATE(2024,8,1) | B24: =SUMIFS(Cleaned_Data!$E$5:$E$5560,Cleaned_Data!$A$5:$A$5560,A24) | C24: =SUMIFS(Cleaned_Data!$K$5:$K$5560,Cleaned_Data!$A$5:$A$5560,A24) | D24: =IFERROR(C24/B24,0) | E24: =IFERROR(B24/B23-1,"") | F24: =IFERROR(B24/B12-1,"") | G24: =SUM($B$5:B24) | H24: =SUM(B22:B24) | I24: =SUM(B13:B24) | J24: =TEXT(A24,"mmmm") | K24: ="Q"&ROUNDUP(MONTH(A24)/3,0)&"-"&YEAR(A24)
A25: =DATE(2024,9,1) | B25: =SUMIFS(Cleaned_Data!$E$5:$E$5560,Cleaned_Data!$A$5:$A$5560,A25) | C25: =SUMIFS(Cleaned_Data!$K$5:$K$5560,Cleaned_Data!$A$5:$A$5560,A25) | D25: =IFERROR(C25/B25,0) | E25: =IFERROR(B25/B24-1,"") | F25: =IFERROR(B25/B13-1,"") | G25: =SUM($B$5:B25) | H25: =SUM(B23:B25) | I25: =SUM(B14:B25) | J25: =TEXT(A25,"mmmm") | K25: ="Q"&ROUNDUP(MONTH(A25)/3,0)&"-"&YEAR(A25)
A26: =DATE(2024,10,1) | B26: =SUMIFS(Cleaned_Data!$E$5:$E$5560,Cleaned_Data!$A$5:$A$5560,A26) | C26: =SUMIFS(Cleaned_Data!$K$5:$K$5560,Cleaned_Data!$A$5:$A$5560,A26) | D26: =IFERROR(C26/B26,0) | E26: =IFERROR(B26/B25-1,"") | F26: =IFERROR(B26/B14-1,"") | G26: =SUM($B$5:B26) | H26: =SUM(B24:B26) | I26: =SUM(B15:B26) | J26: =TEXT(A26,"mmmm") | K26: ="Q"&ROUNDUP(MONTH(A26)/3,0)&"-"&YEAR(A26)
A27: =DATE(2024,11,1) | B27: =SUMIFS(Cleaned_Data!$E$5:$E$5560,Cleaned_Data!$A$5:$A$5560,A27) | C27: =SUMIFS(Cleaned_Data!$K$5:$K$5560,Cleaned_Data!$A$5:$A$5560,A27) | D27: =IFERROR(C27/B27,0) | E27: =IFERROR(B27/B26-1,"") | F27: =IFERROR(B27/B15-1,"") | G27: =SUM($B$5:B27) | H27: =SUM(B25:B27) | I27: =SUM(B16:B27) | J27: =TEXT(A27,"mmmm") | K27: ="Q"&ROUNDUP(MONTH(A27)/3,0)&"-"&YEAR(A27)
A28: =DATE(2024,12,1) | B28: =SUMIFS(Cleaned_Data!$E$5:$E$5560,Cleaned_Data!$A$5:$A$5560,A28) | C28: =SUMIFS(Cleaned_Data!$K$5:$K$5560,Cleaned_Data!$A$5:$A$5560,A28) | D28: =IFERROR(C28/B28,0) | E28: =IFERROR(B28/B27-1,"") | F28: =IFERROR(B28/B16-1,"") | G28: =SUM($B$5:B28) | H28: =SUM(B26:B28) | I28: =SUM(B17:B28) | J28: =TEXT(A28,"mmmm") | K28: ="Q"&ROUNDUP(MONTH(A28)/3,0)&"-"&YEAR(A28)
A29: =DATE(2025,1,1) | B29: =SUMIFS(Cleaned_Data!$E$5:$E$5560,Cleaned_Data!$A$5:$A$5560,A29) | C29: =SUMIFS(Cleaned_Data!$K$5:$K$5560,Cleaned_Data!$A$5:$A$5560,A29) | D29: =IFERROR(C29/B29,0) | E29: =IFERROR(B29/B28-1,"") | F29: =IFERROR(B29/B17-1,"") | G29: =SUM($B$5:B29) | H29: =SUM(B27:B29) | I29: =SUM(B18:B29) | J29: =TEXT(A29,"mmmm") | K29: ="Q"&ROUNDUP(MONTH(A29)/3,0)&"-"&YEAR(A29)
A30: =DATE(2025,2,1) | B30: =SUMIFS(Cleaned_Data!$E$5:$E$5560,Cleaned_Data!$A$5:$A$5560,A30) | C30: =SUMIFS(Cleaned_Data!$K$5:$K$5560,Cleaned_Data!$A$5:$A$5560,A30) | D30: =IFERROR(C30/B30,0) | E30: =IFERROR(B30/B29-1,"") | F30: =IFERROR(B30/B18-1,"") | G30: =SUM($B$5:B30) | H30: =SUM(B28:B30) | I30: =SUM(B19:B30) | J30: =TEXT(A30,"mmmm") | K30: ="Q"&ROUNDUP(MONTH(A30)/3,0)&"-"&YEAR(A30)
A31: =DATE(2025,3,1) | B31: =SUMIFS(Cleaned_Data!$E$5:$E$5560,Cleaned_Data!$A$5:$A$5560,A31) | C31: =SUMIFS(Cleaned_Data!$K$5:$K$5560,Cleaned_Data!$A$5:$A$5560,A31) | D31: =IFERROR(C31/B31,0) | E31: =IFERROR(B31/B30-1,"") | F31: =IFERROR(B31/B19-1,"") | G31: =SUM($B$5:B31) | H31: =SUM(B29:B31) | I31: =SUM(B20:B31) | J31: =TEXT(A31,"mmmm") | K31: ="Q"&ROUNDUP(MONTH(A31)/3,0)&"-"&YEAR(A31)
A32: =DATE(2025,4,1) | B32: =SUMIFS(Cleaned_Data!$E$5:$E$5560,Cleaned_Data!$A$5:$A$5560,A32) | C32: =SUMIFS(Cleaned_Data!$K$5:$K$5560,Cleaned_Data!$A$5:$A$5560,A32) | D32: =IFERROR(C32/B32,0) | E32: =IFERROR(B32/B31-1,"") | F32: =IFERROR(B32/B20-1,"") | G32: =SUM($B$5:B32) | H32: =SUM(B30:B32) | I32: =SUM(B21:B32) | J32: =TEXT(A32,"mmmm") | K32: ="Q"&ROUNDUP(MONTH(A32)/3,0)&"-"&YEAR(A32)
A33: =DATE(2025,5,1) | B33: =SUMIFS(Cleaned_Data!$E$5:$E$5560,Cleaned_Data!$A$5:$A$5560,A33) | C33: =SUMIFS(Cleaned_Data!$K$5:$K$5560,Cleaned_Data!$A$5:$A$5560,A33) | D33: =IFERROR(C33/B33,0) | E33: =IFERROR(B33/B32-1,"") | F33: =IFERROR(B33/B21-1,"") | G33: =SUM($B$5:B33) | H33: =SUM(B31:B33) | I33: =SUM(B22:B33) | J33: =TEXT(A33,"mmmm") | K33: ="Q"&ROUNDUP(MONTH(A33)/3,0)&"-"&YEAR(A33)
A34: =DATE(2025,6,1) | B34: =SUMIFS(Cleaned_Data!$E$5:$E$5560,Cleaned_Data!$A$5:$A$5560,A34) | C34: =SUMIFS(Cleaned_Data!$K$5:$K$5560,Cleaned_Data!$A$5:$A$5560,A34) | D34: =IFERROR(C34/B34,0) | E34: =IFERROR(B34/B33-1,"") | F34: =IFERROR(B34/B22-1,"") | G34: =SUM($B$5:B34) | H34: =SUM(B32:B34) | I34: =SUM(B23:B34) | J34: =TEXT(A34,"mmmm") | K34: ="Q"&ROUNDUP(MONTH(A34)/3,0)&"-"&YEAR(A34)
A35: =DATE(2025,7,1) | B35: =SUMIFS(Cleaned_Data!$E$5:$E$5560,Cleaned_Data!$A$5:$A$5560,A35) | C35: =SUMIFS(Cleaned_Data!$K$5:$K$5560,Cleaned_Data!$A$5:$A$5560,A35) | D35: =IFERROR(C35/B35,0) | E35: =IFERROR(B35/B34-1,"") | F35: =IFERROR(B35/B23-1,"") | G35: =SUM($B$5:B35) | H35: =SUM(B33:B35) | I35: =SUM(B24:B35) | J35: =TEXT(A35,"mmmm") | K35: ="Q"&ROUNDUP(MONTH(A35)/3,0)&"-"&YEAR(A35)
A36: =DATE(2025,8,1) | B36: =SUMIFS(Cleaned_Data!$E$5:$E$5560,Cleaned_Data!$A$5:$A$5560,A36) | C36: =SUMIFS(Cleaned_Data!$K$5:$K$5560,Cleaned_Data!$A$5:$A$5560,A36) | D36: =IFERROR(C36/B36,0) | E36: =IFERROR(B36/B35-1,"") | F36: =IFERROR(B36/B24-1,"") | G36: =SUM($B$5:B36) | H36: =SUM(B34:B36) | I36: =SUM(B25:B36) | J36: =TEXT(A36,"mmmm") | K36: ="Q"&ROUNDUP(MONTH(A36)/3,0)&"-"&YEAR(A36)
A37: =DATE(2025,9,1) | B37: =SUMIFS(Cleaned_Data!$E$5:$E$5560,Cleaned_Data!$A$5:$A$5560,A37) | C37: =SUMIFS(Cleaned_Data!$K$5:$K$5560,Cleaned_Data!$A$5:$A$5560,A37) | D37: =IFERROR(C37/B37,0) | E37: =IFERROR(B37/B36-1,"") | F37: =IFERROR(B37/B25-1,"") | G37: =SUM($B$5:B37) | H37: =SUM(B35:B37) | I37: =SUM(B26:B37) | J37: =TEXT(A37,"mmmm") | K37: ="Q"&ROUNDUP(MONTH(A37)/3,0)&"-"&YEAR(A37)
A38: =DATE(2025,10,1) | B38: =SUMIFS(Cleaned_Data!$E$5:$E$5560,Cleaned_Data!$A$5:$A$5560,A38) | C38: =SUMIFS(Cleaned_Data!$K$5:$K$5560,Cleaned_Data!$A$5:$A$5560,A38) | D38: =IFERROR(C38/B38,0) | E38: =IFERROR(B38/B37-1,"") | F38: =IFERROR(B38/B26-1,"") | G38: =SUM($B$5:B38) | H38: =SUM(B36:B38) | I38: =SUM(B27:B38) | J38: =TEXT(A38,"mmmm") | K38: ="Q"&ROUNDUP(MONTH(A38)/3,0)&"-"&YEAR(A38)
A39: =DATE(2025,11,1) | B39: =SUMIFS(Cleaned_Data!$E$5:$E$5560,Cleaned_Data!$A$5:$A$5560,A39) | C39: =SUMIFS(Cleaned_Data!$K$5:$K$5560,Cleaned_Data!$A$5:$A$5560,A39) | D39: =IFERROR(C39/B39,0) | E39: =IFERROR(B39/B38-1,"") | F39: =IFERROR(B39/B27-1,"") | G39: =SUM($B$5:B39) | H39: =SUM(B37:B39) | I39: =SUM(B28:B39) | J39: =TEXT(A39,"mmmm") | K39: ="Q"&ROUNDUP(MONTH(A39)/3,0)&"-"&YEAR(A39)
A40: =DATE(2025,12,1) | B40: =SUMIFS(Cleaned_Data!$E$5:$E$5560,Cleaned_Data!$A$5:$A$5560,A40) | C40: =SUMIFS(Cleaned_Data!$K$5:$K$5560,Cleaned_Data!$A$5:$A$5560,A40) | D40: =IFERROR(C40/B40,0) | E40: =IFERROR(B40/B39-1,"") | F40: =IFERROR(B40/B28-1,"") | G40: =SUM($B$5:B40) | H40: =SUM(B38:B40) | I40: =SUM(B29:B40) | J40: =TEXT(A40,"mmmm") | K40: ="Q"&ROUNDUP(MONTH(A40)/3,0)&"-"&YEAR(A40)
A43: Year | B43: Revenue | C43: Profit | D43: Margin | E43: YoY %
A44: 2023 | B44: =SUMIFS(Cleaned_Data!$E$5:$E$5560,Cleaned_Data!$M$5:$M$5560,A44) | C44: =SUMIFS(Cleaned_Data!$K$5:$K$5560,Cleaned_Data!$M$5:$M$5560,A44) | D44: =IFERROR(C44/B44,0)
...

Sheet Customer_Analysis
A1: Customer Analysis: RFM segments, lookups and customer KPIs
A2: Type a customer_id in the yellow cell. XLOOKUP and INDEX/MATCH return the details. Segment table uses COUNTIFS/SUMIFS/AVERAGEIFS.
A4: customer_id | B4: full_name | C4: region_name | D4: city | E4: loyalty_member | F4: segment | G4: orders | H4: revenue | I4: profit | J4: first_order | K4: last_order | L4: r_score | M4: f_score | N4: m_score | O4: days_since_last_order | P4: repeat_flag | R4: Customer lookup | S4: Value
A5: C00847 | B5: Aarav Joshi | C5: East | D5: Kolkata | E5: Yes | F5: High Value | G5: 353 | H5: 2202343.2 | I5: 433728.53 | J5: 44931 | K5: 46018 | L5: 5 | M5: 5 | N5: 5 | O5: =DATE(2026,1,1)-K5 | P5: =IF(G5>=2,"Repeat","One-time") | R5: customer_id (input) | S5: C00847
A6: C00579 | B6: Shreya Chopra | C6: South | D6: Bengaluru | E6: Yes | F6: High Value | G6: 203 | H6: 1435246.7 | I6: 263292.74 | J6: 44929 | K6: 45929 | L6: 4 | M6: 5 | N6: 5 | O6: =DATE(2026,1,1)-K6 | P6: =IF(G6>=2,"Repeat","One-time") | R6: Name (XLOOKUP) | S6: =_xlfn.XLOOKUP(S5,Customer_Analysis!$A$5:$A$8806,Customer_Analysis!$B$5:$B$8806,"Not found")
A7: C01429 | B7: Zoya Mehta | C7: South | D7: Coimbatore | E7: Yes | F7: At Risk | G7: 129 | H7: 1139648.7 | I7: 197943.15 | J7: 44995 | K7: 45713 | L7: 2 | M7: 5 | N7: 5 | O7: =DATE(2026,1,1)-K7 | P7: =IF(G7>=2,"Repeat","One-time") | R7: Segment (XLOOKUP) | S7: =_xlfn.XLOOKUP(S5,Customer_Analysis!$A$5:$A$8806,Customer_Analysis!$F$5:$F$8806,"Not found")
A8: C04910 | B8: Nikhil Verma | C8: South | D8: Hyderabad | E8: Yes | F8: High Value | G8: 137 | H8: 1079882.6 | I8: 207726.62 | J8: 45401 | K8: 45789 | L8: 3 | M8: 5 | N8: 5 | O8: =DATE(2026,1,1)-K8 | P8: =IF(G8>=2,"Repeat","One-time") | R8: Name (INDEX/MATCH) | S8: =IFERROR(INDEX(Customer_Analysis!$B$5:$B$8806,MATCH(S5,Customer_Analysis!$A$5:$A$8806,0)),"Not found")
A9: C00994 | B9: Divya Sinha | C9: East | D9: Kolkata | E9: No | F9: High Value | G9: 120 | H9: 951018.85 | I9: 177148.73 | J9: 44934 | K9: 46021 | L9: 5 | M9: 5 | N9: 5 | O9: =DATE(2026,1,1)-K9 | P9: =IF(G9>=2,"Repeat","One-time") | R9: Revenue (INDEX/MATCH) | S9: =IFERROR(INDEX(Customer_Analysis!$H$5:$H$8806,MATCH(S5,Customer_Analysis!$A$5:$A$8806,0)),0)
A10: C00665 | B10: Manish Bose | C10: East | D10: Kolkata | E10: No | F10: High Value | G10: 108 | H10: 862494.53 | I10: 121175.11 | J10: 44932 | K10: 46011 | L10: 5 | M10: 5 | N10: 5 | O10: =DATE(2026,1,1)-K10 | P10: =IF(G10>=2,"Repeat","One-time") | R10: Orders (INDEX/MATCH) | S10: =IFERROR(INDEX(Customer_Analysis!$G$5:$G$8806,MATCH(S5,Customer_Analysis!$A$5:$A$8806,0)),0)
A11: C01337 | B11: Imran Joshi | C11: South | D11: Bengaluru | E11: Yes | F11: At Risk | G11: 121 | H11: 798091.91 | I11: 149003.45 | J11: 44986 | K11: 45634 | L11: 2 | M11: 5 | N11: 5 | O11: =DATE(2026,1,1)-K11 | P11: =IF(G11>=2,"Repeat","One-time") | R11: Revenue rank | S11: =IFERROR(_xlfn.RANK.EQ(S9,Customer_Analysis!$H$5:$H$8806,0),"-")
A12: C06172 | B12: Ayesha Patel | C12: East | D12: Patna | E12: No | F12: High Value | G12: 106 | H12: 768870.21 | I12: 95146.22 | J12: 45518 | K12: 46022 | L12: 5 | M12: 5 | N12: 5 | O12: =DATE(2026,1,1)-K12 | P12: =IF(G12>=2,"Repeat","One-time")
A13: C00870 | B13: Zoya Ghosh | C13: East | D13: Jamshedpur | E13: No | F13: High Value | G13: 97 | H13: 745178.64 | I13: 147052.36 | J13: 44929 | K13: 45875 | L13: 3 | M13: 5 | N13: 5 | O13: =DATE(2026,1,1)-K13 | P13: =IF(G13>=2,"Repeat","One-time")
A14: C03747 | B14: Amit Yadav | C14: South | D14: Kochi | E14: Yes | F14: High Value | G14: 90 | H14: 722850.99 | I14: 127484.6 | J14: 45278 | K14: 46016 | L14: 5 | M14: 5 | N14: 5 | O14: =DATE(2026,1,1)-K14 | P14: =IF(G14>=2,"Repeat","One-time") | R14: Segment | S14: Customers | T14: Revenue | U14: Avg orders | V14: Revenue share | W14: Avg revenue/customer
A15: C06591 | B15: Ritu Thakur | C15: West | D15: Ahmedabad | E15: Yes | F15: High Value | G15: 104 | H15: 710784.72 | I15: 125366.5 | J15: 45556 | K15: 46016 | L15: 5 | M15: 5 | N15: 5 | O15: =DATE(2026,1,1)-K15 | P15: =IF(G15>=2,"Repeat","One-time") | R15: High Value | S15: =COUNTIFS(Customer_Analysis!$F$5:$F$8806,R15) | T15: =SUMIFS(Customer_Analysis!$H$5:$H$8806,Customer_Analysis!$F$5:$F$8806,R15) | U15: =IFERROR(AVERAGEIFS(Customer_Analysis!$G$5:$G$8806,Customer_Analysis!$F$5:$F$8806,R15),0) | V15: =IFERROR(T15/SUM($T$15:$T$20),0) | W15: =IFERROR(T15/S15,0)
A16: C01663 | B16: Tanvi Thakur | C16: West | D16: Mumbai | E16: Yes | F16: High Value | G16: 98 | H16: 686653.8 | I16: 126511 | J16: 45029 | K16: 46014 | L16: 5 | M16: 5 | N16: 5 | O16: =DATE(2026,1,1)-K16 | P16: =IF(G16>=2,"Repeat","One-time") | R16: Loyal | S16: =COUNTIFS(Customer_Analysis!$F$5:$F$8806,R16) | T16: =SUMIFS(Customer_Analysis!$H$5:$H$8806,Customer_Analysis!$F$5:$F$8806,R16) | U16: =IFERROR(AVERAGEIFS(Customer_Analysis!$G$5:$G$8806,Customer_Analysis!$F$5:$F$8806,R16),0) | V16: =IFERROR(T16/SUM($T$15:$T$20),0) | W16: =IFERROR(T16/S16,0)
A17: C04772 | B17: Sanjay Thakur | C17: West | D17: Mumbai | E17: Yes | F17: High Value | G17: 84 | H17: 674057.13 | I17: 99976.2 | J17: 45395 | K17: 46017 | L17: 5 | M17: 5 | N17: 5 | O17: =DATE(2026,1,1)-K17 | P17: =IF(G17>=2,"Repeat","One-time") | R17: New | S17: =COUNTIFS(Customer_Analysis!$F$5:$F$8806,R17) | T17: =SUMIFS(Customer_Analysis!$H$5:$H$8806,Customer_Analysis!$F$5:$F$8806,R17) | U17: =IFERROR(AVERAGEIFS(Customer_Analysis!$G$5:$G$8806,Customer_Analysis!$F$5:$F$8806,R17),0) | V17: =IFERROR(T17/SUM($T$15:$T$20),0) | W17: =IFERROR(T17/S17,0)
A18: C01880 | B18: Neha Mukherjee | C18: North | D18: Lucknow | E18: Yes | F18: At Risk | G18: 94 | H18: 635935.31 | I18: 110496.9 | J18: 45056 | K18: 45320 | L18: 1 | M18: 5 | N18: 5 | O18: =DATE(2026,1,1)-K18 | P18: =IF(G18>=2,"Repeat","One-time") | R18: Occasional | S18: =COUNTIFS(Customer_Analysis!$F$5:$F$8806,R18) | T18: =SUMIFS(Customer_Analysis!$H$5:$H$8806,Customer_Analysis!$F$5:$F$8806,R18) | U18: =IFERROR(AVERAGEIFS(Customer_Analysis!$G$5:$G$8806,Customer_Analysis!$F$5:$F$8806,R18),0) | V18: =IFERROR(T18/SUM($T$15:$T$20),0) | W18: =IFERROR(T18/S18,0)
A19: C01969 | B19: Arjun Sinha | C19: South | D19: Hyderabad | E19: Yes | F19: High Value | G19: 58 | H19: 631870.51 | I19: 114405.77 | J19: 45092 | K19: 46008 | L19: 5 | M19: 5 | N19: 5 | O19: =DATE(2026,1,1)-K19 | P19: =IF(G19>=2,"Repeat","One-time") | R19: At Risk | S19: =COUNTIFS(Customer_Analysis!$F$5:$F$8806,R19) | T19: =SUMIFS(Customer_Analysis!$H$5:$H$8806,Customer_Analysis!$F$5:$F$8806,R19) | U19: =IFERROR(AVERAGEIFS(Customer_Analysis!$G$5:$G$8806,Customer_Analysis!$F$5:$F$8806,R19),0) | V19: =IFERROR(T19/SUM($T$15:$T$20),0) | W19: =IFERROR(T19/S19,0)
A20: C00375 | B20: Priya Sinha | C20: South | D20: Kochi | E20: No | F20: High Value | G20: 88 | H20: 631767.45 | I20: 135696.87 | J20: 44927 | K20: 45834 | L20: 3 | M20: 5 | N20: 5 | O20: =DATE(2026,1,1)-K20 | P20: =IF(G20>=2,"Repeat","One-time") | R20: Hibernating | S20: =COUNTIFS(Customer_Analysis!$F$5:$F$8806,R20) | T20: =SUMIFS(Customer_Analysis!$H$5:$H$8806,Customer_Analysis!$F$5:$F$8806,R20) | U20: =IFERROR(AVERAGEIFS(Customer_Analysis!$G$5:$G$8806,Customer_Analysis!$F$5:$F$8806,R20),0) | V20: =IFERROR(T20/SUM($T$15:$T$20),0) | W20: =IFERROR(T20/S20,0)
A21: C02140 | B21: Manish Gupta | C21: South | D21: Bengaluru | E21: Yes | F21: High Value | G21: 83 | H21: 631491.74 | I21: 107831.29 | J21: 45095 | K21: 46019 | L21: 5 | M21: 5 | N21: 5 | O21: =DATE(2026,1,1)-K21 | P21: =IF(G21>=2,"Repeat","One-time")
A22: C02684 | B22: Sanjay Das | C22: South | D22: Chennai | E22: Yes | F22: High Value | G22: 61 | H22: 615364.14 | I22: 100855.92 | J22: 45167 | K22: 45986 | L22: 4 | M22: 5 | N22: 5 | O22: =DATE(2026,1,1)-K22 | P22: =IF(G22>=2,"Repeat","One-time")
A23: C05078 | B23: Varun Nair | C23: North | D23: Gurugram | E23: Yes | F23: High Value | G23: 65 | H23: 603236.37 | I23: 100776.62 | J23: 45422 | K23: 45999 | L23: 5 | M23: 5 | N23: 5 | O23: =DATE(2026,1,1)-K23 | P23: =IF(G23>=2,"Repeat","One-time") | R23: Repeat customer % | S23: =COUNTIFS(Customer_Analysis!$P$5:$P$8806,"Repeat")/COUNTA(Customer_Analysis!$A$5:$A$8806)
A24: C02255 | B24: Manish Bose | C24: South | D24: Chennai | E24: No | F24: At Risk | G24: 70 | H24: 596389.99 | I24: 113492.9 | J24: 45104 | K24: 45641 | L24: 2 | M24: 5 | N24: 5 | O24: =DATE(2026,1,1)-K24 | P24: =IF(G24>=2,"Repeat","One-time") | R24: Loyalty filter (select) | S24: Yes
A25: C00610 | B25: Pooja Pillai | C25: South | D25: Chennai | E25: No | F25: At Risk | G25: 79 | H25: 593859.18 | I25: 134081.27 | J25: 44930 | K25: 45586 | L25: 2 | M25: 5 | N25: 5 | O25: =DATE(2026,1,1)-K25 | P25: =IF(G25>=2,"Repeat","One-time") | R25: Avg orders for selection | S25: =AVERAGEIFS(Customer_Analysis!$G$5:$G$8806,Customer_Analysis!$E$5:$E$8806,S24)
A26: C00668 | B26: Priya Gupta | C26: East | D26: Kolkata | E26: Yes | F26: At Risk | G26: 87 | H26: 589576.82 | I26: 105921.33 | J26: 44929 | K26: 45613 | L26: 2 | M26: 5 | N26: 5 | O26: =DATE(2026,1,1)-K26 | P26: =IF(G26>=2,"Repeat","One-time")
A27: C00055 | B27: Ananya Iyer | C27: West | D27: Pune | E27: Yes | F27: High Value | G27: 88 | H27: 585240.15 | I27: 102481.05 | J27: 44949 | K27: 46003 | L27: 5 | M27: 5 | N27: 5 | O27: =DATE(2026,1,1)-K27 | P27: =IF(G27>=2,"Repeat","One-time")
A28: C02615 | B28: Suresh Patel | C28: South | D28: Bengaluru | E28: Yes | F28: High Value | G28: 65 | H28: 582793.12 | I28: 96091.26 | J28: 45145 | K28: 45988 | L28: 5 | M28: 5 | N28: 5 | O28: =DATE(2026,1,1)-K28 | P28: =IF(G28>=2,"Repeat","One-time")
A29: C00587 | B29: Kavya Das | C29: North | D29: Delhi | E29: No | F29: High Value | G29: 86 | H29: 561102.22 | I29: 100566.83 | J29: 44941 | K29: 46022 | L29: 5 | M29: 5 | N29: 5 | O29: =DATE(2026,1,1)-K29 | P29: =IF(G29>=2,"Repeat","One-time")
A30: C02552 | B30: Arjun Kapoor | C30: East | D30: Patna | E30: No | F30: High Value | G30: 59 | H30: 543664.9 | I30: 90121.13 | J30: 45155 | K30: 46022 | L30: 5 | M30: 5 | N30: 5 | O30: =DATE(2026,1,1)-K30 | P30: =IF(G30>=2,"Repeat","One-time")
A31: C03796 | B31: Diya Agarwal | C31: East | D31: Guwahati | E31: No | F31: High Value | G31: 63 | H31: 542122.65 | I31: 96768.87 | J31: 45300 | K31: 46002 | L31: 5 | M31: 5 | N31: 5 | O31: =DATE(2026,1,1)-K31 | P31: =IF(G31>=2,"Repeat","One-time")
A32: C00862 | B32: Tanvi Joshi | C32: West | D32: Mumbai | E32: Yes | F32: High Value | G32: 73 | H32: 536871 | I32: 89936.19 | J32: 44930 | K32: 46019 | L32: 5 | M32: 5 | N32: 5 | O32: =DATE(2026,1,1)-K32 | P32: =IF(G32>=2,"Repeat","One-time")
A33: C00225 | B33: Ananya Verma | C33: Central | D33: Bhopal | E33: No | F33: High Value | G33: 100 | H33: 521804.77 | I33: 110428.79 | J33: 44939 | K33: 45871 | L33: 3 | M33: 5 | N33: 5 | O33: =DATE(2026,1,1)-K33 | P33: =IF(G33>=2,"Repeat","One-time")
A34: C00904 | B34: Isha Sinha | C34: West | D34: Mumbai | E34: Yes | F34: High Value | G34: 52 | H34: 508653.65 | I34: 57228.45 | J34: 44930 | K34: 46014 | L34: 5 | M34: 5 | N34: 5 | O34: =DATE(2026,1,1)-K34 | P34: =IF(G34>=2,"Repeat","One-time")
A35: C01720 | B35: Rahul Bose | C35: West | D35: Mumbai | E35: Yes | F35: High Value | G35: 60 | H35: 507602.27 | I35: 80560.07 | J35: 45037 | K35: 46011 | L35: 5 | M35: 5 | N35: 5 | O35: =DATE(2026,1,1)-K35 | P35: =IF(G35>=2,"Repeat","One-time")
A36: C06677 | B36: Aarav Sharma | C36: West | D36: Ahmedabad | E36: No | F36: High Value | G36: 64 | H36: 505517.86 | I36: 86003.52 | J36: 45566 | K36: 46009 | L36: 5 | M36: 5 | N36: 5 | O36: =DATE(2026,1,1)-K36 | P36: =IF(G36>=2,"Repeat","One-time")
A37: C00980 | B37: Aditya Pillai | C37: West | D37: Ahmedabad | E37: Yes | F37: At Risk | G37: 50 | H37: 504312.18 | I37: 58628.36 | J37: 44932 | K37: 45396 | L37: 1 | M37: 5 | N37: 5 | O37: =DATE(2026,1,1)-K37 | P37: =IF(G37>=2,"Repeat","One-time")
... A8806: C02858 | B8806: Ananya Kapoor | C8806: North | D8806: Delhi | E8806: No | F8806: Occasional | G8806: 1 | H8806: 135.31 | I8806: 46.87 | J8806: 45922 | K8806: 45922 | L8806: 3 | M8806: 1 | N8806: 1 | O8806: =DATE(2026,1,1)-K8806 | P8806: =IF(G8806>=2,"Repeat","One-time")

Sheet Product_Analysis
A1: Product Analysis: margin, return rate, rank and tier (formulas)
A4: product_id | B4: product_name | C4: category | D4: revenue | E4: profit | F4: units | G4: lines | H4: returned_lines | I4: margin | J4: return_rate | K4: revenue_rank | L4: tier | M4: cum_share | O4: Pareto check | P4: Value
A5: P0389 | B5: Haveli Audio 515 | C5: Electronics | D5: 37844313 | E5: 2836742.3 | F5: 2282 | G5: 1830 | H5: 148 | I5: =IFERROR(E5/D5,0) | J5: =IFERROR(H5/G5,0) | K5: =_xlfn.RANK.EQ(D5,$D$5:$D$524,0) | L5: =_xlfn.IFS(K5<=20,"Top 20",K5>500,"Bottom 20",TRUE,"Core") | M5: =SUM($D$5:D5)/SUM($D$5:$D$524) | O5: Products for 80% of revenue | P5: =COUNTIFS(M5:M524,"<=0.8")
A6: P0310 | B6: Trendo Accessories 219 | C6: Electronics | D6: 14927226 | E6: 1837076.4 | F6: 1017 | G6: 823 | H6: 77 | I6: =IFERROR(E6/D6,0) | J6: =IFERROR(H6/G6,0) | K6: =_xlfn.RANK.EQ(D6,$D$5:$D$524,0) | L6: =_xlfn.IFS(K6<=20,"Top 20",K6>500,"Bottom 20",TRUE,"Core") | M6: =SUM($D$5:D6)/SUM($D$5:$D$524) | O6: Share of catalogue | P6: =P5/COUNTA(A5:A524)
A7: P0429 | B7: Solace Audio 726 | C7: Electronics | D7: 12075562 | E7: 1515862.4 | F7: 1209 | G7: 968 | H7: 71 | I7: =IFERROR(E7/D7,0) | J7: =IFERROR(H7/G7,0) | K7: =_xlfn.RANK.EQ(D7,$D$5:$D$524,0) | L7: =_xlfn.IFS(K7<=20,"Top 20",K7>500,"Bottom 20",TRUE,"Core") | M7: =SUM($D$5:D7)/SUM($D$5:$D$524) | O7: Loss-making products | P7: =COUNTIFS(E5:E524,"<0")
A8: P0422 | B8: Veltrix Accessories 688 | C8: Electronics | D8: 10610997 | E8: 464749.96 | F8: 100 | G8: 79 | H8: 9 | I8: =IFERROR(E8/D8,0) | J8: =IFERROR(H8/G8,0) | K8: =_xlfn.RANK.EQ(D8,$D$5:$D$524,0) | L8: =_xlfn.IFS(K8<=20,"Top 20",K8>500,"Bottom 20",TRUE,"Core") | M8: =SUM($D$5:D8)/SUM($D$5:$D$524)
A9: P0099 | B9: Vayu Wearables 419 | C9: Electronics | D9: 10017178 | E9: 343911.44 | F9: 485 | G9: 395 | H9: 37 | I9: =IFERROR(E9/D9,0) | J9: =IFERROR(H9/G9,0) | K9: =_xlfn.RANK.EQ(D9,$D$5:$D$524,0) | L9: =_xlfn.IFS(K9<=20,"Top 20",K9>500,"Bottom 20",TRUE,"Core") | M9: =SUM($D$5:D9)/SUM($D$5:$D$524)
A10: P0341 | B10: Kavya Audio 985 | C10: Electronics | D10: 7873637.6 | E10: 411729.25 | F10: 419 | G10: 351 | H10: 27 | I10: =IFERROR(E10/D10,0) | J10: =IFERROR(H10/G10,0) | K10: =_xlfn.RANK.EQ(D10,$D$5:$D$524,0) | L10: =_xlfn.IFS(K10<=20,"Top 20",K10>500,"Bottom 20",TRUE,"Core") | M10: =SUM($D$5:D10)/SUM($D$5:$D$524)
A11: P0175 | B11: Pragati Wearables 108 | C11: Electronics | D11: 7368396.5 | E11: 1088154.1 | F11: 488 | G11: 392 | H11: 29 | I11: =IFERROR(E11/D11,0) | J11: =IFERROR(H11/G11,0) | K11: =_xlfn.RANK.EQ(D11,$D$5:$D$524,0) | L11: =_xlfn.IFS(K11<=20,"Top 20",K11>500,"Bottom 20",TRUE,"Core") | M11: =SUM($D$5:D11)/SUM($D$5:$D$524)
A12: P0231 | B12: UrbanLeaf Smartphones 334 | C12: Electronics | D12: 6570781.1 | E12: 283340.87 | F12: 409 | G12: 334 | H12: 33 | I12: =IFERROR(E12/D12,0) | J12: =IFERROR(H12/G12,0) | K12: =_xlfn.RANK.EQ(D12,$D$5:$D$524,0) | L12: =_xlfn.IFS(K12<=20,"Top 20",K12>500,"Bottom 20",TRUE,"Core") | M12: =SUM($D$5:D12)/SUM($D$5:$D$524)
A13: P0269 | B13: UrbanLeaf Wearables 980 | C13: Electronics | D13: 6481117.1 | E13: 392225.2 | F13: 378 | G13: 309 | H13: 25 | I13: =IFERROR(E13/D13,0) | J13: =IFERROR(H13/G13,0) | K13: =_xlfn.RANK.EQ(D13,$D$5:$D$524,0) | L13: =_xlfn.IFS(K13<=20,"Top 20",K13>500,"Bottom 20",TRUE,"Core") | M13: =SUM($D$5:D13)/SUM($D$5:$D$524)
A14: P0375 | B14: Nexora Audio 391 | C14: Electronics | D14: 4812011.1 | E14: 481225.45 | F14: 136 | G14: 100 | H14: 9 | I14: =IFERROR(E14/D14,0) | J14: =IFERROR(H14/G14,0) | K14: =_xlfn.RANK.EQ(D14,$D$5:$D$524,0) | L14: =_xlfn.IFS(K14<=20,"Top 20",K14>500,"Bottom 20",TRUE,"Core") | M14: =SUM($D$5:D14)/SUM($D$5:$D$524)
A15: P0350 | B15: Zephyr Accessories 759 | C15: Electronics | D15: 4663291 | E15: 604170.47 | F15: 150 | G15: 112 | H15: 9 | I15: =IFERROR(E15/D15,0) | J15: =IFERROR(H15/G15,0) | K15: =_xlfn.RANK.EQ(D15,$D$5:$D$524,0) | L15: =_xlfn.IFS(K15<=20,"Top 20",K15>500,"Bottom 20",TRUE,"Core") | M15: =SUM($D$5:D15)/SUM($D$5:$D$524)
A16: P0171 | B16: Kriti Women Apparel 576 | C16: Fashion | D16: 4583611.1 | E16: 2463127.2 | F16: 1258 | G16: 993 | H16: 164 | I16: =IFERROR(E16/D16,0) | J16: =IFERROR(H16/G16,0) | K16: =_xlfn.RANK.EQ(D16,$D$5:$D$524,0) | L16: =_xlfn.IFS(K16<=20,"Top 20",K16>500,"Bottom 20",TRUE,"Core") | M16: =SUM($D$5:D16)/SUM($D$5:$D$524)
A17: P0007 | B17: Kavya Team Sports 395 | C17: Sports | D17: 3812533.8 | E17: 1281575.9 | F17: 815 | G17: 654 | H17: 45 | I17: =IFERROR(E17/D17,0) | J17: =IFERROR(H17/G17,0) | K17: =_xlfn.RANK.EQ(D17,$D$5:$D$524,0) | L17: =_xlfn.IFS(K17<=20,"Top 20",K17>500,"Bottom 20",TRUE,"Core") | M17: =SUM($D$5:D17)/SUM($D$5:$D$524)
A18: P0091 | B18: Haveli Laptops 553 | C18: Electronics | D18: 3722830.8 | E18: 157739.14 | F18: 181 | G18: 142 | H18: 15 | I18: =IFERROR(E18/D18,0) | J18: =IFERROR(H18/G18,0) | K18: =_xlfn.RANK.EQ(D18,$D$5:$D$524,0) | L18: =_xlfn.IFS(K18<=20,"Top 20",K18>500,"Bottom 20",TRUE,"Core") | M18: =SUM($D$5:D18)/SUM($D$5:$D$524)
A19: P0281 | B19: Kavya Smartphones 272 | C19: Electronics | D19: 3379375.4 | E19: 373443.05 | F19: 114 | G19: 98 | H19: 8 | I19: =IFERROR(E19/D19,0) | J19: =IFERROR(H19/G19,0) | K19: =_xlfn.RANK.EQ(D19,$D$5:$D$524,0) | L19: =_xlfn.IFS(K19<=20,"Top 20",K19>500,"Bottom 20",TRUE,"Core") | M19: =SUM($D$5:D19)/SUM($D$5:$D$524)
... A524: P0305 | B524: UrbanLeaf Children 406 | C524: Books | D524: 4859.02 | E524: 1733.26 | F524: 22 | G524: 16 | H524: 0 | I524: =IFERROR(E524/D524,0) | J524: =IFERROR(H524/G524,0) | K524: =_xlfn.RANK.EQ(D524,$D$5:$D$524,0) | L524: =_xlfn.IFS(K524<=20,"Top 20",K524>500,"Bottom 20",TRUE,"Core") | M524: =SUM($D$5:D524)/SUM($D$5:$D$524)

Sheet Regional_Analysis
A1: Regional & Channel Analysis (SUMIFS over Cleaned_Data)
A4: Region | B4: Revenue | C4: Profit | D4: Margin | E4: Revenue share | F4: Return rate | G4: Performance
A5: North | B5: =SUMIFS(Cleaned_Data!$E$5:$E$5560,Cleaned_Data!$B$5:$B$5560,A5) | C5: =SUMIFS(Cleaned_Data!$K$5:$K$5560,Cleaned_Data!$B$5:$B$5560,A5) | D5: =IFERROR(C5/B5,0) | E5: =IFERROR(B5/SUM($B$5:$B$9),0) | F5: =IFERROR(SUMIFS(Cleaned_Data!$J$5:$J$5560,Cleaned_Data!$B$5:$B$5560,A5)/SUMIFS(Cleaned_Data!$I$5:$I$5560,Cleaned_Data!$B$5:$B$5560,A5),0) | G5: =IF(E5>=0.25,"Leader",IF(E5>=0.15,"Core","Growth market"))
A6: South | B6: =SUMIFS(Cleaned_Data!$E$5:$E$5560,Cleaned_Data!$B$5:$B$5560,A6) | C6: =SUMIFS(Cleaned_Data!$K$5:$K$5560,Cleaned_Data!$B$5:$B$5560,A6) | D6: =IFERROR(C6/B6,0) | E6: =IFERROR(B6/SUM($B$5:$B$9),0) | F6: =IFERROR(SUMIFS(Cleaned_Data!$J$5:$J$5560,Cleaned_Data!$B$5:$B$5560,A6)/SUMIFS(Cleaned_Data!$I$5:$I$5560,Cleaned_Data!$B$5:$B$5560,A6),0) | G6: =IF(E6>=0.25,"Leader",IF(E6>=0.15,"Core","Growth market"))
A7: East | B7: =SUMIFS(Cleaned_Data!$E$5:$E$5560,Cleaned_Data!$B$5:$B$5560,A7) | C7: =SUMIFS(Cleaned_Data!$K$5:$K$5560,Cleaned_Data!$B$5:$B$5560,A7) | D7: =IFERROR(C7/B7,0) | E7: =IFERROR(B7/SUM($B$5:$B$9),0) | F7: =IFERROR(SUMIFS(Cleaned_Data!$J$5:$J$5560,Cleaned_Data!$B$5:$B$5560,A7)/SUMIFS(Cleaned_Data!$I$5:$I$5560,Cleaned_Data!$B$5:$B$5560,A7),0) | G7: =IF(E7>=0.25,"Leader",IF(E7>=0.15,"Core","Growth market"))
A8: West | B8: =SUMIFS(Cleaned_Data!$E$5:$E$5560,Cleaned_Data!$B$5:$B$5560,A8) | C8: =SUMIFS(Cleaned_Data!$K$5:$K$5560,Cleaned_Data!$B$5:$B$5560,A8) | D8: =IFERROR(C8/B8,0) | E8: =IFERROR(B8/SUM($B$5:$B$9),0) | F8: =IFERROR(SUMIFS(Cleaned_Data!$J$5:$J$5560,Cleaned_Data!$B$5:$B$5560,A8)/SUMIFS(Cleaned_Data!$I$5:$I$5560,Cleaned_Data!$B$5:$B$5560,A8),0) | G8: =IF(E8>=0.25,"Leader",IF(E8>=0.15,"Core","Growth market"))
A9: Central | B9: =SUMIFS(Cleaned_Data!$E$5:$E$5560,Cleaned_Data!$B$5:$B$5560,A9) | C9: =SUMIFS(Cleaned_Data!$K$5:$K$5560,Cleaned_Data!$B$5:$B$5560,A9) | D9: =IFERROR(C9/B9,0) | E9: =IFERROR(B9/SUM($B$5:$B$9),0) | F9: =IFERROR(SUMIFS(Cleaned_Data!$J$5:$J$5560,Cleaned_Data!$B$5:$B$5560,A9)/SUMIFS(Cleaned_Data!$I$5:$I$5560,Cleaned_Data!$B$5:$B$5560,A9),0) | G9: =IF(E9>=0.25,"Leader",IF(E9>=0.15,"Core","Growth market"))
A12: Channel | B12: Revenue | C12: Profit | D12: Margin | E12: Revenue share | F12: Return rate | G12: Avg discount
A13: Website | B13: =SUMIFS(Cleaned_Data!$E$5:$E$5560,Cleaned_Data!$C$5:$C$5560,A13) | C13: =SUMIFS(Cleaned_Data!$K$5:$K$5560,Cleaned_Data!$C$5:$C$5560,A13) | D13: =IFERROR(C13/B13,0) | E13: =IFERROR(B13/SUM($B$13:$B$17),0) | F13: =IFERROR(SUMIFS(Cleaned_Data!$J$5:$J$5560,Cleaned_Data!$C$5:$C$5560,A13)/SUMIFS(Cleaned_Data!$I$5:$I$5560,Cleaned_Data!$C$5:$C$5560,A13),0) | G13: =IFERROR(1-B13/SUMIFS(Cleaned_Data!$G$5:$G$5560,Cleaned_Data!$C$5:$C$5560,A13),0)
A14: Mobile App | B14: =SUMIFS(Cleaned_Data!$E$5:$E$5560,Cleaned_Data!$C$5:$C$5560,A14) | C14: =SUMIFS(Cleaned_Data!$K$5:$K$5560,Cleaned_Data!$C$5:$C$5560,A14) | D14: =IFERROR(C14/B14,0) | E14: =IFERROR(B14/SUM($B$13:$B$17),0) | F14: =IFERROR(SUMIFS(Cleaned_Data!$J$5:$J$5560,Cleaned_Data!$C$5:$C$5560,A14)/SUMIFS(Cleaned_Data!$I$5:$I$5560,Cleaned_Data!$C$5:$C$5560,A14),0) | G14: =IFERROR(1-B14/SUMIFS(Cleaned_Data!$G$5:$G$5560,Cleaned_Data!$C$5:$C$5560,A14),0)
A15: Marketplace | B15: =SUMIFS(Cleaned_Data!$E$5:$E$5560,Cleaned_Data!$C$5:$C$5560,A15) | C15: =SUMIFS(Cleaned_Data!$K$5:$K$5560,Cleaned_Data!$C$5:$C$5560,A15) | D15: =IFERROR(C15/B15,0) | E15: =IFERROR(B15/SUM($B$13:$B$17),0) | F15: =IFERROR(SUMIFS(Cleaned_Data!$J$5:$J$5560,Cleaned_Data!$C$5:$C$5560,A15)/SUMIFS(Cleaned_Data!$I$5:$I$5560,Cleaned_Data!$C$5:$C$5560,A15),0) | G15: =IFERROR(1-B15/SUMIFS(Cleaned_Data!$G$5:$G$5560,Cleaned_Data!$C$5:$C$5560,A15),0)
A16: Retail Store | B16: =SUMIFS(Cleaned_Data!$E$5:$E$5560,Cleaned_Data!$C$5:$C$5560,A16) | C16: =SUMIFS(Cleaned_Data!$K$5:$K$5560,Cleaned_Data!$C$5:$C$5560,A16) | D16: =IFERROR(C16/B16,0) | E16: =IFERROR(B16/SUM($B$13:$B$17),0) | F16: =IFERROR(SUMIFS(Cleaned_Data!$J$5:$J$5560,Cleaned_Data!$C$5:$C$5560,A16)/SUMIFS(Cleaned_Data!$I$5:$I$5560,Cleaned_Data!$C$5:$C$5560,A16),0) | G16: =IFERROR(1-B16/SUMIFS(Cleaned_Data!$G$5:$G$5560,Cleaned_Data!$C$5:$C$5560,A16),0)
A17: Unknown | B17: =SUMIFS(Cleaned_Data!$E$5:$E$5560,Cleaned_Data!$C$5:$C$5560,A17) | C17: =SUMIFS(Cleaned_Data!$K$5:$K$5560,Cleaned_Data!$C$5:$C$5560,A17) | D17: =IFERROR(C17/B17,0) | E17: =IFERROR(B17/SUM($B$13:$B$17),0) | F17: =IFERROR(SUMIFS(Cleaned_Data!$J$5:$J$5560,Cleaned_Data!$C$5:$C$5560,A17)/SUMIFS(Cleaned_Data!$I$5:$I$5560,Cleaned_Data!$C$5:$C$5560,A17),0) | G17: =IFERROR(1-B17/SUMIFS(Cleaned_Data!$G$5:$G$5560,Cleaned_Data!$C$5:$C$5560,A17),0)

Sheet Returns_Analysis
A1: Returns Analysis: COUNTIFS / SUMIFS over the returns register
A4: return_id | B4: order_id | C4: order_date | D4: category | E4: region_name | F4: channel_name | G4: return_reason | H4: return_qty | I4: refund_amount | K4: Return reason | L4: Returns | M4: Refund value | N4: Share
A5: RET000001 | B5: O000003 | C5: 44927 | D5: Sports | E5: East | F5: Website | G5: Damaged in Transit | H5: 1 | I5: 729 | K5: Size/Fit Issue | L5: =COUNTIFS(Returns_Analysis!$G$5:$G$8827,K5) | M5: =SUMIFS(Returns_Analysis!$I$5:$I$8827,Returns_Analysis!$G$5:$G$8827,K5) | N5: =IFERROR(L5/SUM($L$5:$L$12),0)
A6: RET000002 | B6: O000007 | C6: 44927 | D6: Fashion | E6: East | F6: Marketplace | G6: Size/Fit Issue | H6: 1 | I6: 3446.1 | K6: Defective Product | L6: =COUNTIFS(Returns_Analysis!$G$5:$G$8827,K6) | M6: =SUMIFS(Returns_Analysis!$I$5:$I$8827,Returns_Analysis!$G$5:$G$8827,K6) | N6: =IFERROR(L6/SUM($L$5:$L$12),0)
A7: RET000003 | B7: O000012 | C7: 44927 | D7: Fashion | E7: Central | F7: Website | G7: Not as Described | H7: 1 | I7: 670.65 | K7: Damaged in Transit | L7: =COUNTIFS(Returns_Analysis!$G$5:$G$8827,K7) | M7: =SUMIFS(Returns_Analysis!$I$5:$I$8827,Returns_Analysis!$G$5:$G$8827,K7) | N7: =IFERROR(L7/SUM($L$5:$L$12),0)
A8: RET000004 | B8: O000018 | C8: 44927 | D8: Fashion | E8: South | F8: Website | G8: Wrong Item Delivered | H8: 1 | I8: 1072.55 | K8: Not as Described | L8: =COUNTIFS(Returns_Analysis!$G$5:$G$8827,K8) | M8: =SUMIFS(Returns_Analysis!$I$5:$I$8827,Returns_Analysis!$G$5:$G$8827,K8) | N8: =IFERROR(L8/SUM($L$5:$L$12),0)
A9: RET000005 | B9: O000022 | C9: 44927 | D9: Fashion | E9: South | F9: Unknown | G9: Changed Mind | H9: 1 | I9: 1043.1 | K9: Changed Mind | L9: =COUNTIFS(Returns_Analysis!$G$5:$G$8827,K9) | M9: =SUMIFS(Returns_Analysis!$I$5:$I$8827,Returns_Analysis!$G$5:$G$8827,K9) | N9: =IFERROR(L9/SUM($L$5:$L$12),0)
A10: RET000006 | B10: O000030 | C10: 44927 | D10: Fashion | E10: Central | F10: Marketplace | G10: Size/Fit Issue | H10: 1 | I10: 1394.1 | K10: Wrong Item Delivered | L10: =COUNTIFS(Returns_Analysis!$G$5:$G$8827,K10) | M10: =SUMIFS(Returns_Analysis!$I$5:$I$8827,Returns_Analysis!$G$5:$G$8827,K10) | N10: =IFERROR(L10/SUM($L$5:$L$12),0)
A11: RET000007 | B11: O000040 | C11: 44927 | D11: Fashion | E11: East | F11: Marketplace | G11: Size/Fit Issue | H11: 2 | I11: 2055.3 | K11: Late Delivery | L11: =COUNTIFS(Returns_Analysis!$G$5:$G$8827,K11) | M11: =SUMIFS(Returns_Analysis!$I$5:$I$8827,Returns_Analysis!$G$5:$G$8827,K11) | N11: =IFERROR(L11/SUM($L$5:$L$12),0)
A12: RET000008 | B12: O000049 | C12: 44927 | D12: Electronics | E12: North | F12: Marketplace | G12: Damaged in Transit | H12: 1 | I12: 3464.1 | K12: Not Specified | L12: =COUNTIFS(Returns_Analysis!$G$5:$G$8827,K12) | M12: =SUMIFS(Returns_Analysis!$I$5:$I$8827,Returns_Analysis!$G$5:$G$8827,K12) | N12: =IFERROR(L12/SUM($L$5:$L$12),0)
A13: RET000009 | B13: O000051 | C13: 44927 | D13: Electronics | E13: North | F13: Website | G13: Defective Product | H13: 1 | I13: 11826.55
A14: RET000010 | B14: O000056 | C14: 44928 | D14: Fashion | E14: North | F14: Unknown | G14: Not as Described | H14: 1 | I14: 2357.1
A15: RET000011 | B15: O000058 | C15: 44928 | D15: Sports | E15: North | F15: Marketplace | G15: Not as Described | H15: 1 | I15: 656.1 | K15: Category | L15: Returns | M15: Sold lines | N15: Return rate | O15: Flag
A16: RET000012 | B16: O000058 | C16: 44928 | D16: Fashion | E16: North | F16: Marketplace | G16: Size/Fit Issue | H16: 1 | I16: 977.55 | K16: Electronics | L16: =COUNTIFS(Returns_Analysis!$D$5:$D$8827,K16) | M16: =SUMIFS(Cleaned_Data!$I$5:$I$5560,Cleaned_Data!$D$5:$D$5560,K16) | N16: =IFERROR(L16/M16,0) | O16: =IF(N16>0.1,"High - investigate","OK")
A17: RET000013 | B17: O000060 | C17: 44928 | D17: Home & Kitchen | E17: East | F17: Mobile App | G17: Not as Described | H17: 1 | I17: 1907.1 | K17: Fashion | L17: =COUNTIFS(Returns_Analysis!$D$5:$D$8827,K17) | M17: =SUMIFS(Cleaned_Data!$I$5:$I$5560,Cleaned_Data!$D$5:$D$5560,K17) | N17: =IFERROR(L17/M17,0) | O17: =IF(N17>0.1,"High - investigate","OK")
A18: RET000014 | B18: O000069 | C18: 44928 | D18: Sports | E18: South | F18: Website | G18: Late Delivery | H18: 1 | I18: 656.1 | K18: Home & Kitchen | L18: =COUNTIFS(Returns_Analysis!$D$5:$D$8827,K18) | M18: =SUMIFS(Cleaned_Data!$I$5:$I$5560,Cleaned_Data!$D$5:$D$5560,K18) | N18: =IFERROR(L18/M18,0) | O18: =IF(N18>0.1,"High - investigate","OK")
A19: RET000015 | B19: O000071 | C19: 44928 | D19: Fashion | E19: East | F19: Website | G19: Changed Mind | H19: 1 | I19: 1016.1 | K19: Sports | L19: =COUNTIFS(Returns_Analysis!$D$5:$D$8827,K19) | M19: =SUMIFS(Cleaned_Data!$I$5:$I$5560,Cleaned_Data!$D$5:$D$5560,K19) | N19: =IFERROR(L19/M19,0) | O19: =IF(N19>0.1,"High - investigate","OK")
A20: RET000016 | B20: O000085 | C20: 44929 | D20: Fashion | E20: North | F20: Website | G20: Size/Fit Issue | H20: 1 | I20: 521.1 | K20: Grocery | L20: =COUNTIFS(Returns_Analysis!$D$5:$D$8827,K20) | M20: =SUMIFS(Cleaned_Data!$I$5:$I$5560,Cleaned_Data!$D$5:$D$5560,K20) | N20: =IFERROR(L20/M20,0) | O20: =IF(N20>0.1,"High - investigate","OK")
A21: RET000017 | B21: O000098 | C21: 44929 | D21: Fashion | E21: South | F21: Marketplace | G21: Size/Fit Issue | H21: 1 | I21: 1052.1 | K21: Beauty | L21: =COUNTIFS(Returns_Analysis!$D$5:$D$8827,K21) | M21: =SUMIFS(Cleaned_Data!$I$5:$I$5560,Cleaned_Data!$D$5:$D$5560,K21) | N21: =IFERROR(L21/M21,0) | O21: =IF(N21>0.1,"High - investigate","OK")
A22: RET000018 | B22: O000099 | C22: 44929 | D22: Sports | E22: West | F22: Website | G22: Damaged in Transit | H22: 1 | I22: 4427.1 | K22: Books | L22: =COUNTIFS(Returns_Analysis!$D$5:$D$8827,K22) | M22: =SUMIFS(Cleaned_Data!$I$5:$I$5560,Cleaned_Data!$D$5:$D$5560,K22) | N22: =IFERROR(L22/M22,0) | O22: =IF(N22>0.1,"High - investigate","OK")
A23: RET000019 | B23: O000102 | C23: 44929 | D23: Fashion | E23: South | F23: Marketplace | G23: Size/Fit Issue | H23: 1 | I23: 847.2
A24: RET000020 | B24: O000121 | C24: 44930 | D24: Beauty | E24: South | F24: Mobile App | G24: Wrong Item Delivered | H24: 1 | I24: 132.05
A25: RET000021 | B25: O000122 | C25: 44930 | D25: Sports | E25: South | F25: Website | G25: Late Delivery | H25: 1 | I25: 1419
A26: RET000022 | B26: O000126 | C26: 44930 | D26: Fashion | E26: West | F26: Mobile App | G26: Size/Fit Issue | H26: 2 | I26: 1906.2
A27: RET000023 | B27: O000128 | C27: 44930 | D27: Home & Kitchen | E27: South | F27: Mobile App | G27: Wrong Item Delivered | H27: 1 | I27: 1937.05
A28: RET000024 | B28: O000131 | C28: 44930 | D28: Fashion | E28: Central | F28: Mobile App | G28: Size/Fit Issue | H28: 1 | I28: 3637.55
A29: RET000025 | B29: O000159 | C29: 44931 | D29: Fashion | E29: Central | F29: Marketplace | G29: Changed Mind | H29: 1 | I29: 1394.1
A30: RET000026 | B30: O000160 | C30: 44931 | D30: Home & Kitchen | E30: West | F30: Marketplace | G30: Defective Product | H30: 1 | I30: 2583.05
A31: RET000027 | B31: O000161 | C31: 44931 | D31: Sports | E31: West | F31: Mobile App | G31: Defective Product | H31: 1 | I31: 692.55
A32: RET000028 | B32: O000167 | C32: 44932 | D32: Electronics | E32: West | F32: Marketplace | G32: Damaged in Transit | H32: 1 | I32: 14848.65
A33: RET000029 | B33: O000173 | C33: 44932 | D33: Sports | E33: West | F33: Mobile App | G33: Damaged in Transit | H33: 1 | I33: 692.55
A34: RET000030 | B34: O000175 | C34: 44932 | D34: Sports | E34: West | F34: Mobile App | G34: Wrong Item Delivered | H34: 1 | I34: 1025.1
... A8827: RET008849 | B8827: O055979 | C8827: 46022 | D8827: Fashion | E8827: North | F8827: Retail Store | G8827: Size/Fit Issue | H8827: 1 | I8827: 1933.64

Sheet Pivot_Analysis
A1: Pivot Analysis: formula cross-tabs + pivot-style chart
A2: Native PivotTable: Insert > PivotTable > Table 'tblSales' (Cleaned_Data). Rows=category, Columns=year, Values=Sum of revenue. See excel/README.md
A4: Category | B4: 2023 | C4: 2024 | D4: 2025 | E4: Total | F4: CAGR 23-25
A5: Electronics | B5: =SUMIFS(Cleaned_Data!$E$5:$E$5560,Cleaned_Data!$D$5:$D$5560,$A5,Cleaned_Data!$M$5:$M$5560,2023) | C5: =SUMIFS(Cleaned_Data!$E$5:$E$5560,Cleaned_Data!$D$5:$D$5560,$A5,Cleaned_Data!$M$5:$M$5560,2024) | D5: =SUMIFS(Cleaned_Data!$E$5:$E$5560,Cleaned_Data!$D$5:$D$5560,$A5,Cleaned_Data!$M$5:$M$5560,2025) | E5: =SUM(B5:D5) | F5: =IFERROR((D5/B5)^(1/2)-1,"")
